<?xml version="1.0" encoding="utf-8"?>

<robot name="arm" xmlns:xacro="http://www.ros.org/wiki/xacro">

  <xacro:property name="mass_base" value="2" />
  <xacro:property name="mass_upper_arm" value="5" />
  <xacro:property name="mass_forearm" value="2" />
  <xacro:property name="mass_wrist" value="2" />
  <xacro:property name="mass_claw_base" value="0.5" />
  <xacro:property name="mass_claw" value="1" />

  <!-- <xacro:include filename="$(find simulation)/robot/arm.gazebo" /> -->
  <!-- <origin rpy="0 0 1.5707" xyz="0 0 0"/> -->
  <!-- <link name="world"/> -->
  <link name='arm_base_link'>
    <inertial>
      <mass value="1e-5" />
      <origin xyz="0 0 0" rpy="0 0 0"/>
      <inertia ixx="1e-6" ixy="0" ixz="0" iyy="1e-6" iyz="0" izz="1e-6" />
    </inertial>
  </link>

  <link name='base'>

    <collision name='collision'>
      <!-- <origin rpy="0.0 0 0" xyz="0 0 0.0477"/> -->
      <geometry>
        <!-- <box size="0.0422 0.0785 0.0953"/> -->
        <mesh filename="package://simulation/robot/arm_parts/base.dae"/>
      </geometry>
    </collision>

    <visual name='visual'>
      <origin rpy="0 0 0" xyz="0 0 0"/>
      <geometry>
        <!-- <box size="0.0422 0.0785 0.0953"/> -->
        <mesh filename="package://simulation/robot/arm_parts/base.dae"/>
      </geometry>
    </visual>
  </link>
  <joint type="continuous" name="base_arm_hinge">
    <origin xyz="0 0 0" rpy="0 0 0"/>
    <axis xyz="0 0 1" />
    <child link="base"/>
    <parent link="arm_base_link"/>
  </joint>


  <link name='upper_arm'>
    <collision name='collision'>
      <!-- <origin rpy="0 0 0" xyz="0 0 0.253"/> -->
      <origin rpy="0 0 0" xyz="0 0 -0.0216"/>
      <geometry>
        <!-- <box size="0.0432 0.0594 0.507"/> -->
        <mesh filename="package://simulation/robot/arm_parts/upper_arm.dae"/>
      </geometry>
    </collision>

    <visual name='visual'>
      <origin rpy="0 0 0" xyz="0 0 -0.0216"/>
      <geometry>
        <!-- <box size="0.0432 0.0594 0.507"/> -->
        <mesh filename="package://simulation/robot/arm_parts/upper_arm.dae"/>
      </geometry>
    </visual>
  </link>

  <link name='forearm'>
    <collision name='collision'>
      <origin rpy="0 0 0" xyz="0 0 0.118"/>
      <geometry>
        <box size="0.0424 0.0785 0.237"/>
      </geometry>
    </collision>

    <visual name='visual'>
      <origin rpy="0 0 0" xyz="0 0 -0.0216"/>
      <geometry>
        <!-- <box size="0.0424 0.0785 0.237"/> -->
        <mesh filename="package://simulation/robot/arm_parts/forearm.dae"/>
      </geometry>
    </visual>

  </link>

  <link name='wrist'>
    <collision name='collision'>
      <origin rpy="0 0 0" xyz="0 0 0.0217"/>
      <geometry>
        <box size="0.0432 0.0595 0.0865"/>
      </geometry>
    </collision>

    <visual name='visual'>
      <origin rpy="0 0 0" xyz="0 0 -0.0064"/>
      <geometry>
        <!-- <box size="0.0432 0.0595 0.0865"/> -->
        <mesh filename="package://simulation/robot/arm_parts/wrist.dae"/>
      </geometry>
    </visual>

  </link>

  <link name='claw_base'>
    <collision name='collision'>
      <origin rpy="0 0 0" xyz="0 0 0.05"/>
      <geometry>
        <box size="0.0064 0.1045 0.1"/>
      </geometry>
    </collision>

    <visual name='visual'>
      <origin rpy="0 0 0" xyz="0 0 0"/>
      <geometry>
        <!-- <box size="0.0424 0.0785 0.237"/> -->
        <mesh filename="package://simulation/robot/arm_parts/claw_base.dae"/>
      </geometry>
    </visual>

  </link>

  <link name='claw_right'>
    <collision name='collision'>
      <origin rpy="0 0 0" xyz="0 0 0"/>
      <geometry>
        <mesh filename="package://simulation/robot/arm_parts/claw.dae"/>
      </geometry>
      <surface>
        <friction>
          <ode>
            <mu>1.4</mu>
            <mu2>1.4</mu2>
          </ode>
        </friction>
      </surface>
      <contact>
        <ode>
          <mu>1.4</mu>
          <mu2>1.4</mu2>
          <min_depth>0.003</min_depth>
          <max_vel>0</max_vel>
        </ode>
      </contact>
    </collision>

    <visual name='visual'>
      <origin rpy="0 0 0" xyz="0 0 0"/>
      <geometry>
        <!-- <box size="0.0424 0.0785 0.237"/> -->
        <mesh filename="package://simulation/robot/arm_parts/claw.dae"/>
      </geometry>
    </visual>

  </link>

  <link name='claw_left'>
    <collision name='collision'>
      <origin rpy="0 0 0" xyz="0 0 0"/>
      <geometry>
        <mesh filename="package://simulation/robot/arm_parts/claw.dae"/>
      </geometry>
      <surface>
        <friction>
          <ode>
            <mu>1.4</mu>
            <mu2>1.4</mu2>
          </ode>
        </friction>
      </surface>
      c<contact>
        <ode>
          <mu>1.4</mu>
          <mu2>1.4</mu2>
          <min_depth>0.003</min_depth>
          <max_vel>0</max_vel>
        </ode>
      </contact>
    </collision>

    <visual name='visual'>
      <origin rpy="0 0 0" xyz="0 0 0"/>
      <geometry>
        <!-- <box size="0.0424 0.0785 0.237"/> -->
        <mesh filename="package://simulation/robot/arm_parts/claw.dae"/>
      </geometry>
    </visual>

  </link>


  <joint type="continuous" name="lower_hinge">
    <!-- <limit upper="1.57" lower="-1.57" velocity="5" effort="1000000"/> -->
    <origin xyz="0 0 0.074"/>
    <axis xyz="0 1 0" />
    <child link="upper_arm"/>
    <parent link="base"/>
  </joint>

  <joint type="continuous" name="upper_hinge">
    <!-- <limit upper="1.57" lower="-1.57" velocity="5" effort="10000"/> -->
    <origin xyz="0 0.0 0.507"/>
    <axis xyz="0 1 0" />
    <child link="forearm"/>
    <parent link="upper_arm"/>
  </joint>

  <joint type="revolute" name="forearm_hinge">
    <limit upper="1.57" lower="-1.57" velocity="5" effort="10000"/>
    <origin xyz="0 0.0 0.237"/>
    <axis xyz="0 1 0" />
    <child link="wrist"/>
    <parent link="forearm"/>
  </joint>

  <joint type="revolute" name="wrist_hinge">
    <limit upper="6.28" lower="-6.28" velocity="1" effort="0.5"/>
    <origin xyz="0 0.0 0.107"/>
    <axis xyz="0 0 1" />
    <child link="claw_base"/>
    <parent link="wrist"/>
  </joint>

  <joint type="revolute" name="claw_right_hinge">
    <limit upper="1.57" lower="0" velocity="0.001" effort="5"/>
    <origin xyz="0 -0.04175 0.128"/>
    <axis xyz="1 0 0" />
    <child link="claw_right"/>
    <parent link="claw_base"/>
  </joint>

  <joint type="revolute" name="claw_left_hinge">
    <limit upper="1.57" lower="0" velocity="0.1" effort="5"/>
    <origin xyz="0 0.04175 0.128" rpy="0 0 3.14"/>
    <axis xyz="1 0 0" />
    <child link="claw_left"/>
    <parent link="claw_base"/>
  </joint>
</robot>
