<?xml version="1.0" encoding="utf-8" ?>
<!-- =================================================================================== -->
<!-- |    This document was autogenerated by xacro from /home/veerash/Rover/ROS_WS/src/simulation/robot/arm_moveit.xacro | -->
<!-- |    EDITING THIS FILE BY HAND IS NOT RECOMMENDED                                 | -->
<!-- =================================================================================== -->
<robot name="arm">
    <!-- <xacro:include filename="$(find simulation)/robot/arm.gazebo" /> -->
    <!-- <origin rpy="0 0 1.5707" xyz="0 0 0"/> -->
    <!-- <link name="world"/> -->
    <link name="base">
        <collision name="collision">
            <!-- <origin rpy="0.0 0 0" xyz="0 0 0.0477"/> -->
            <geometry>
                <!-- <box size="0.0422 0.0785 0.0953"/> -->
                <mesh filename="package://simulation/robot/arm_parts/base.dae" />
            </geometry>
        </collision>
        <visual name="visual">
            <origin rpy="0 0 0" xyz="0 0 0" />
            <geometry>
                <!-- <box size="0.0422 0.0785 0.0953"/> -->
                <mesh filename="package://simulation/robot/arm_parts/base.dae" />
            </geometry>
        </visual>
        
<inertial>
            <mass value="0.1" />
            <inertia ixx="0.03" iyy="0.03" izz="0.03" ixy="0.0" ixz="0.0" iyz="0.0" />
        </inertial>

    </link>
    <link name="upper_arm">
        <collision name="collision">
            <!-- <origin rpy="0 0 0" xyz="0 0 0.253"/> -->
            <origin rpy="0 0 0" xyz="0 0 -0.0216" />
            <geometry>
                <!-- <box size="0.0432 0.0594 0.507"/> -->
                <mesh filename="package://simulation/robot/arm_parts/upper_arm.dae" />
            </geometry>
        </collision>
        <visual name="visual">
            <origin rpy="0 0 0" xyz="0 0 -0.0216" />
            <geometry>
                <!-- <box size="0.0432 0.0594 0.507"/> -->
                <mesh filename="package://simulation/robot/arm_parts/upper_arm.dae" />
            </geometry>
        </visual>
        
<inertial>
            <mass value="0.1" />
            <inertia ixx="0.03" iyy="0.03" izz="0.03" ixy="0.0" ixz="0.0" iyz="0.0" />
        </inertial>

    </link>
    <link name="forearm">
        <collision name="collision">
            <origin rpy="0 0 0" xyz="0 0 0.118" />
            <geometry>
                <box size="0.0424 0.0785 0.237" />
            </geometry>
        </collision>
        <visual name="visual">
            <origin rpy="0 0 0" xyz="0 0 -0.0216" />
            <geometry>
                <!-- <box size="0.0424 0.0785 0.237"/> -->
                <mesh filename="package://simulation/robot/arm_parts/forearm.dae" />
            </geometry>
        </visual>
        
<inertial>
            <mass value="0.1" />
            <inertia ixx="0.03" iyy="0.03" izz="0.03" ixy="0.0" ixz="0.0" iyz="0.0" />
        </inertial>

    </link>
    <link name="wrist">
        <collision name="collision">
            <origin rpy="0 0 0" xyz="0 0 0.0217" />
            <geometry>
                <box size="0.0432 0.0595 0.0865" />
            </geometry>
        </collision>
        <visual name="visual">
            <origin rpy="0 0 0" xyz="0 0 -0.0064" />
            <geometry>
                <!-- <box size="0.0432 0.0595 0.0865"/> -->
                <mesh filename="package://simulation/robot/arm_parts/wrist.dae" />
            </geometry>
        </visual>
        
<inertial>
            <mass value="0.1" />
            <inertia ixx="0.03" iyy="0.03" izz="0.03" ixy="0.0" ixz="0.0" iyz="0.0" />
        </inertial>

    </link>
    <link name="claw_base">
        <collision name="collision">
            <origin rpy="0 0 0" xyz="0 0 0.05" />
            <geometry>
                <box size="0.0064 0.1045 0.1" />
            </geometry>
        </collision>
        <visual name="visual">
            <origin rpy="0 0 0" xyz="0 0 0" />
            <geometry>
                <!-- <box size="0.0424 0.0785 0.237"/> -->
                <mesh filename="package://simulation/robot/arm_parts/claw_base.dae" />
            </geometry>
        </visual>
        
<inertial>
            <mass value="0.1" />
            <inertia ixx="0.03" iyy="0.03" izz="0.03" ixy="0.0" ixz="0.0" iyz="0.0" />
        </inertial>

    </link>
    <link name="claw_right">
        <collision name="collision">
            <origin rpy="0 0 0" xyz="0 0 0" />
            <geometry>
                <mesh filename="package://simulation/robot/arm_parts/claw.dae" />
            </geometry>
            <surface>
                <friction>
                    <ode>
                        <mu>1.4</mu>
                        <mu2>1.4</mu2>
                    </ode>
                </friction>
            </surface>
            <contact>
                <ode>
                    <mu>1.4</mu>
                    <mu2>1.4</mu2>
                    <min_depth>0.003</min_depth>
                    <max_vel>0</max_vel>
                </ode>
            </contact>
        </collision>
        <visual name="visual">
            <origin rpy="0 0 0" xyz="0 0 0" />
            <geometry>
                <!-- <box size="0.0424 0.0785 0.237"/> -->
                <mesh filename="package://simulation/robot/arm_parts/claw.dae" />
            </geometry>
        </visual>
        
<inertial>
            <mass value="0.1" />
            <inertia ixx="0.03" iyy="0.03" izz="0.03" ixy="0.0" ixz="0.0" iyz="0.0" />
        </inertial>

    </link>
    <link name="claw_left">
        <collision name="collision">
            <origin rpy="0 0 0" xyz="0 0 0" />
            <geometry>
                <mesh filename="package://simulation/robot/arm_parts/claw.dae" />
            </geometry>
            <surface>
                <friction>
                    <ode>
                        <mu>1.4</mu>
                        <mu2>1.4</mu2>
                    </ode>
                </friction>
            </surface>
            c
            <contact>
                <ode>
                    <mu>1.4</mu>
                    <mu2>1.4</mu2>
                    <min_depth>0.003</min_depth>
                    <max_vel>0</max_vel>
                </ode>
            </contact>
        </collision>
        <visual name="visual">
            <origin rpy="0 0 0" xyz="0 0 0" />
            <geometry>
                <!-- <box size="0.0424 0.0785 0.237"/> -->
                <mesh filename="package://simulation/robot/arm_parts/claw.dae" />
            </geometry>
        </visual>
        
<inertial>
            <mass value="0.1" />
            <inertia ixx="0.03" iyy="0.03" izz="0.03" ixy="0.0" ixz="0.0" iyz="0.0" />
        </inertial>

    </link>
    <joint name="lower_hinge" type="continuous">
        <!-- <limit upper="1.57" lower="-1.57" velocity="5" effort="1000000"/> -->
        <origin xyz="0 0 0.074" />
        <axis xyz="0 1 0" />
        <child link="upper_arm" />
        <parent link="base" />
    </joint>
    <joint name="upper_hinge" type="continuous">
        <!-- <limit upper="1.57" lower="-1.57" velocity="5" effort="10000"/> -->
        <origin xyz="0 0.0 0.507" />
        <axis xyz="0 1 0" />
        <child link="forearm" />
        <parent link="upper_arm" />
    </joint>
    <joint name="forearm_hinge" type="revolute">
        <limit effort="10000" lower="-1.57" upper="1.57" velocity="5" />
        <origin xyz="0 0.0 0.237" />
        <axis xyz="0 1 0" />
        <child link="wrist" />
        <parent link="forearm" />
    </joint>
    <joint name="wrist_hinge" type="revolute">
        <limit effort="0.5" lower="-6.28" upper="6.28" velocity="1" />
        <origin xyz="0 0.0 0.107" />
        <axis xyz="0 0 1" />
        <child link="claw_base" />
        <parent link="wrist" />
    </joint>
    <joint name="claw_right_hinge" type="revolute">
        <limit effort="5" lower="0" upper="1.57" velocity="0.001" />
        <origin xyz="0 -0.04175 0.128" />
        <axis xyz="1 0 0" />
        <child link="claw_right" />
        <parent link="claw_base" />
    </joint>
    <joint name="claw_left_hinge" type="revolute">
        <limit effort="5" lower="0" upper="1.57" velocity="0.1" />
        <origin rpy="0 0 3.14" xyz="0 0.04175 0.128" />
        <axis xyz="1 0 0" />
        <child link="claw_left" />
        <parent link="claw_base" />
    </joint>
    
<transmission name="trans_lower_hinge">
        <type>transmission_interface/SimpleTransmission</type>
        <joint name="lower_hinge">
            <hardwareInterface>hardware_interface/EffortJointInterface</hardwareInterface>
        </joint>
        <actuator name="lower_hinge_motor">
            <hardwareInterface>hardware_interface/EffortJointInterface</hardwareInterface>
            <mechanicalReduction>1</mechanicalReduction>
        </actuator>
    </transmission>
    <transmission name="trans_upper_hinge">
        <type>transmission_interface/SimpleTransmission</type>
        <joint name="upper_hinge">
            <hardwareInterface>hardware_interface/EffortJointInterface</hardwareInterface>
        </joint>
        <actuator name="upper_hinge_motor">
            <hardwareInterface>hardware_interface/EffortJointInterface</hardwareInterface>
            <mechanicalReduction>1</mechanicalReduction>
        </actuator>
    </transmission>
    <transmission name="trans_forearm_hinge">
        <type>transmission_interface/SimpleTransmission</type>
        <joint name="forearm_hinge">
            <hardwareInterface>hardware_interface/EffortJointInterface</hardwareInterface>
        </joint>
        <actuator name="forearm_hinge_motor">
            <hardwareInterface>hardware_interface/EffortJointInterface</hardwareInterface>
            <mechanicalReduction>1</mechanicalReduction>
        </actuator>
    </transmission>
    <transmission name="trans_wrist_hinge">
        <type>transmission_interface/SimpleTransmission</type>
        <joint name="wrist_hinge">
            <hardwareInterface>hardware_interface/EffortJointInterface</hardwareInterface>
        </joint>
        <actuator name="wrist_hinge_motor">
            <hardwareInterface>hardware_interface/EffortJointInterface</hardwareInterface>
            <mechanicalReduction>1</mechanicalReduction>
        </actuator>
    </transmission>
    <transmission name="trans_claw_right_hinge">
        <type>transmission_interface/SimpleTransmission</type>
        <joint name="claw_right_hinge">
            <hardwareInterface>hardware_interface/EffortJointInterface</hardwareInterface>
        </joint>
        <actuator name="claw_right_hinge_motor">
            <hardwareInterface>hardware_interface/EffortJointInterface</hardwareInterface>
            <mechanicalReduction>1</mechanicalReduction>
        </actuator>
    </transmission>
    <transmission name="trans_claw_left_hinge">
        <type>transmission_interface/SimpleTransmission</type>
        <joint name="claw_left_hinge">
            <hardwareInterface>hardware_interface/EffortJointInterface</hardwareInterface>
        </joint>
        <actuator name="claw_left_hinge_motor">
            <hardwareInterface>hardware_interface/EffortJointInterface</hardwareInterface>
            <mechanicalReduction>1</mechanicalReduction>
        </actuator>
    </transmission>
    <gazebo>
        <plugin name="gazebo_ros_control" filename="libgazebo_ros_control.so">
            <robotNamespace>/</robotNamespace>
        </plugin>
    </gazebo>
</robot>