<?xml version='1.0'?>

<robot name="rover_with_arm" xmlns:xacro="http://www.ros.org/wiki/xacro">

  <xacro:include filename="$(find simulation)/robot/rover.gazebo" />
  <xacro:include filename="$(find simulation)/robot/arm.xacro" />
  <!-- <xacro:include filename="$(find simulation)/robot/sensors/_d435.urdf.xacro" /> -->
  <xacro:include filename="$(find simulation)/robot/sensors/d435.xacro" />

  <origin rpy="0 0 1.5707" xyz="0 0 0"/>
  <link name='chassis'>
    <pose>0 0 0.1 0 0 0</pose>

    <collision name='collision'>
      <origin rpy="0 0 1.5707" xyz="0 0 -0.1"/>
      <geometry>
        <box size="0.7 1.0 0.3"/>
      </geometry>
      <surface>
        <friction>
          <ode>
            <mu>0</mu>
            <mu2>0</mu2>
            <slip1>1.0</slip1>
            <slip2>1.0</slip2>
          </ode>
        </friction>
      </surface>
    </collision>

    <visual name='chassis_visual'>
      <!-- <pose>-0.25 0.18 -0.04 0 0 0</pose> -->
      <origin rpy="0 0 0" xyz="0 0 -0.04"/>
      <geometry>
        <mesh filename="package://simulation/robot/chassis_with_wheels.dae"/>
      </geometry>
    </visual>
    <inertial>
      <mass value="20.0"/>
      <origin xyz="0 0 -0.1" rpy=" 0 0 1.5707"/>
      <inertia
          ixx="1.0" ixy="0" ixz="0"
          iyy="1.0" iyz="0"
          izz="0.5"
      />
    </inertial>
  </link>
  
  <!-- Arm joint -->
  <joint type="fixed" name="arm_joint">
    <origin xyz="0.3372 0 0.0637" rpy="0 0 0"/>
    <child link="arm_base_link"/>
    <parent link="chassis"/>
  </joint>

  <!-- Stereo camera -->
  <!-- <xacro:sensor_d435 parent="chassis" use_nominal_extrinsics="true" add_plug="false">
    <origin xyz="0 0 0.5" rpy="0 0 0"/>
  </xacro:sensor_d435> -->
  <xacro:realsense-rs200 prefix="" parent="chassis">
      <origin xyz="-0.4 0 0.3637" rpy="0 0 0" />   
  </xacro:realsense-rs200>



  <!-- Kinect Link -->
  <!-- <link name='kinect_link'>
    <inertial>
      <origin xyz="0 0 0" rpy="0 0 0"/>
      <mass value="0.1"/>
      <inertia ixx="1e-6" ixy="0" ixz="0" iyy="1e-6" iyz="0" izz="1e-6" />
    </inertial>
    <collision name="collision">
      <origin xyz="-0.02 0 0" rpy="0 0 0"/>
        <geometry>
          <box size="0.073000 0.276000 0.072000"/>
        </geometry>
    </collision>
    <visual name="visual">
      <origin rpy="0 0 0" xyz="0 0 0"/>
      <geometry>
        <mesh filename="package://simulation/robot/kinect.dae"/>
      </geometry>
    </visual>
  </link>
  <joint name="kinect_joint" type="fixed">
    <axis xyz="0 1 0" />
    <origin xyz="0.5 0 -0.09" rpy="0 0 0"/>
    <parent link="chassis"/>
    <child link="kinect_link"/>
  </joint> -->


  <!-- Camera -->
  <!-- <link name="camera_link1">
    <collision>
      <origin xyz="0 0 0" rpy="0 0 0"/>
      <geometry>
    <box size="0.05 0.05 0.05"/>
      </geometry>
    </collision>

    <visual>
      <origin xyz="0 0 0" rpy="0 0 0"/>
      <geometry>
    <box size="0.05 0.05 0.05"/>
      </geometry>
      <material name="red"/>
    </visual>

      <inertial>
        <mass value="1e-5" />
        <origin xyz="0 0 0" rpy="0 0 0"/>
        <inertia ixx="1e-6" ixy="0" ixz="0" iyy="1e-6" iyz="0" izz="1e-6" />
      </inertial>
  </link>
  <joint name="camera_joint1" type="fixed">
    <axis xyz="0 1 0" />
    <origin xyz="0.45 0.1 0.4" rpy="0 0 0"/>
    <parent link="chassis"/>
    <child link="camera_link1"/>
  </joint> -->

    <!-- Camera -->
  <!-- <link name="camera_link2">
    <collision>
      <origin xyz="0 0 0" rpy="0 0 0"/>
      <geometry>
    <box size="0.05 0.05 0.05"/>
      </geometry>
    </collision>

    <visual>
      <origin xyz="0 0 0" rpy="0 0 0"/>
      <geometry>
    <box size="0.05 0.05 0.05"/>
      </geometry>
      <material name="red"/>
    </visual>

    <inertial>
      <mass value="1e-5" />
      <origin xyz="0 0 0" rpy="0 0 0"/>
      <inertia ixx="1e-6" ixy="0" ixz="0" iyy="1e-6" iyz="0" izz="1e-6" />
    </inertial>
  </link>
  <joint name="camera_joint2" type="fixed">
    <axis xyz="0 1 0" />
    <origin xyz="0.45 -0.1 0.4" rpy="0 0 0"/>
    <parent link="chassis"/>
    <child link="camera_link2"/>
  </joint> -->

  <!-- Hokuyo Laser -->
  <!-- <link name="hokuyo_link">
    <collision>
      <origin xyz="0 0 0" rpy="0 0 0"/>
      <geometry>
    <box size="0.1 0.1 0.1"/>
      </geometry>
    </collision>

    <visual>
      <origin xyz="0 0 0" rpy="0 0 0"/>
      <geometry>
        <mesh filename="package://simulation/models/hokuyo_laser/hokuyo.dae"/>
      </geometry>
    </visual>

    <inertial>
      <mass value="1e-5" />
      <origin xyz="0 0 0" rpy="0 0 0"/>
      <inertia ixx="1e-6" ixy="0" ixz="0" iyy="1e-6" iyz="0" izz="1e-6" />
    </inertial>
  </link>
  
  <joint name="hokuyo_joint" type="fixed">
    <axis xyz="0 1 0" />
    <origin xyz="0.2 0 0.14" rpy="0 0 0"/>
    <parent link="chassis"/>
    <child link="hokuyo_link"/>
  </joint> -->

  <!-- IMU sensor -->
  <!-- <link name="imu_link">
    <inertial>
      <mass value="1e-5" />
      <origin xyz="0 0 0" rpy="0 0 0"/>
      <inertia ixx="1e-6" ixy="0" ixz="0" iyy="1e-6" iyz="0" izz="1e-6" />
    </inertial>   
    <visual>
        <geometry>
            <box size = "0.1 0.1 0.1"/> 
        </geometry>
    </visual>
    <collision>         
        <geometry>
            <box size = "0.1 0.1 0.1"/> 
        </geometry>
    </collision>     
  </link>
  <joint name="imu_joint" type="fixed">
    <axis xyz="0 1 0" />
    <origin xyz="0.0 0 0.027" rpy="0 0 0"/>
    <parent link="chassis"/>
    <child link="imu_link"/>
  </joint> -->

  <!-- GPS sensor -->
  <!-- <link name="gps_link">
    <inertial>
      <mass value="1e-5" />
      <origin xyz="0 0 0" rpy="0 0 0"/>
      <inertia ixx="1e-6" ixy="0" ixz="0" iyy="1e-6" iyz="0" izz="1e-6" />
    </inertial>   
    <visual>
        <geometry>
            <box size = "0.001 0.001 0.001"/> 
        </geometry>
    </visual>
    <collision>         
        <geometry>
            <box size = "0.001 0.001 0.001"/> 
        </geometry>
    </collision>     
  </link>
  <joint name="gps_joint" type="fixed">
    <axis xyz="0 1 0" />
    <origin xyz="-0.1 0 0.027" rpy="0 0 0"/>
    <parent link="chassis"/>
    <child link="gps_link"/>
  </joint> -->


  <link name="left_wheel">
    <!-- <origin xyz="0.5 0.145 -0.31" rpy="0 1.5707 0"/> -->
    <collision name="collision">
      <origin xyz="0 0 0" rpy="0 0 0"/>
      <geometry>
        <cylinder radius="0.1" length="0.05"/>
      </geometry>
    </collision>
    <visual name="left_wheel_visual">
      <origin xyz="0 0 0" rpy="0 0 0"/>
      <geometry>
        <cylinder radius="0.1" length="0.05"/>
      </geometry>
    </visual>
    <inertial>
      <origin xyz="0 0 0" rpy="0 0 0"/>
      <mass value="5"/>
      <cylinder_inertia m="5" r="0.1" h="0.05"/>
      <inertia
        ixx="1.0" ixy="0.0" ixz="0.0"
        iyy="1.0" iyz="0.0"
        izz="1.0"/>
    </inertial>
  </link>

  <link name="front_left_wheel">
    <!-- <origin xyz="0.5 -0.468 -0.38" rpy="0 1.5707 0"/> -->
    <collision name="collision">
      <origin xyz="0 0 0" rpy="0 0 0"/>
      <geometry>
        <cylinder radius="0.1" length="0.05"/>
      </geometry>
    </collision>
    <visual name="visual">
      <origin xyz="0 0 0" rpy="0 0 0"/>
      <geometry>
        <cylinder radius="0.1" length="0.05"/>
      </geometry>
    </visual>
    <inertial>
      <origin xyz="0 0 0" rpy="0 0 0"/>
      <mass value="5"/>
      <cylinder_inertia m="5" r="0.1" h="0.05"/>
      <inertia
        ixx="1.0" ixy="0.0" ixz="0.0"
        iyy="1.0" iyz="0.0"
        izz="1.0"/>
    </inertial>
  </link>

  <link name="right_wheel">
    <!-- <origin xyz="-0.44 0.145 -0.31" rpy="0 1.5707 0"/> -->
    <collision name="collision">
      <origin xyz="0 0 0" rpy="0 0 0"/>
      <geometry>
        <cylinder radius="0.1" length="0.05"/>
      </geometry>
    </collision>
    <visual name="visual">
      <origin xyz="0 0 0" rpy="0 0 0"/>
      <geometry>
        <cylinder radius="0.1" length="0.05"/>
      </geometry>
    </visual>
    <inertial>
      <origin xyz="0 0 0" rpy="0 0 0"/>
      <mass value="5"/>
      <cylinder_inertia m="5" r="0.1" h="0.05"/>
      <inertia
        ixx="1.0" ixy="0.0" ixz="0.0"
        iyy="1.0" iyz="0.0"
        izz="1.0"/>
    </inertial>
  </link>
  
  <link name="front_right_wheel">
    <!-- <origin xyz="-0.44 -0.468 -0.38" rpy="0 1.5707 0"/> -->
    <collision name="collision">
      <origin xyz="0 0 0" rpy="0 0 0"/>
      <geometry>
        <cylinder radius="0.1" length="0.05"/>
      </geometry>
    </collision>
    <visual name="visual">
      <origin xyz="0 0 0" rpy="0 0 0"/>
      <geometry>
        <cylinder radius="0.1" length="0.05"/>
      </geometry>
    </visual>
    <inertial>
      <origin xyz="0 0 0" rpy="0 0 0"/>
      <mass value="5"/>
      <cylinder_inertia m="5" r="0.1" h="0.05"/>
      <inertia
        ixx="1.0" ixy="0.0" ixz="0.0"
        iyy="1.0" iyz="0.0"
        izz="1.0"/>
    </inertial>
  </link>


  <joint type="continuous" name="left_wheel_hinge">
    <origin xyz="0.045 0.49 -0.41" rpy="0 1.5707 1.5707"/>
    <child link="left_wheel"/>
    <parent link="chassis"/>
    <axis xyz="0 0 1" rpy="0 0 0"/>
    <limit effort="100" velocity="100"/>
    <joint_properties damping="0.0" friction="0.0"/>
  </joint>

  <joint type="continuous" name="front_left_wheel_hinge">
    <origin xyz="0.64 0.49 -0.38" rpy="0 1.5707 1.5707"/>
    <child link="front_left_wheel"/>
    <parent link="chassis"/>
    <axis xyz="0 0 1" rpy="0 0 0"/>
    <limit effort="100" velocity="100"/>
    <joint_properties damping="0.0" friction="0.0"/>
  </joint>

  <joint type="continuous" name="front_right_wheel_hinge">
    <origin xyz="0.64 -0.48 -0.38" rpy="0 1.5707 1.5707"/>
    <child link="front_right_wheel"/>
    <parent link="chassis"/>
    <axis xyz="0 0 1" rpy="0 0 0"/>
    <limit effort="100" velocity="100"/>
    <joint_properties damping="0.0" friction="0.0"/>
  </joint>

  <joint type="continuous" name="right_wheel_hinge">
    <origin xyz="0.045 -0.48 -0.41" rpy="0 1.5707 1.5707"/>
    <child link="right_wheel"/>
    <parent link="chassis"/>
    <axis xyz="0 0 1" rpy="0 0 0"/>
    <limit effort="100" velocity="100"/>
    <joint_properties damping="0.0" friction="0.0"/>
  </joint>
</robot>
